Workbook

Sheet metadata
A2: Last edits made by: B. Smith, 2025-06-03rd
A4: Calibration_Input METADATA
A5: Column | B5: Units or levels | C5: Description
A6: watershed_group | B6: - | C6: Watershed group name based on geographic groupings within the Fraser River watershed
A7: run_timing_group | B7: - | C7: Run timing grouping used by fisheries management
A8: CU | B8: - | C8: Conservation Unit relating to the Wild Salmon Policy
A9: gazetted_stream_name | B9: - | C9: Gazetted stream name, not necessarily common-use stream name.
A10: stream_alias | B10: - | C10: Alias to above gazetted stream name. For reference only.
A11: year | B11: - | C11: Escapement year
A12: system_stability | B12: Volatile; Stable | C12: Whether system is considered volatile or stable in its flashiness. E.g., systems lake-fed are stable, while rainwater-fed are volatile (flashy)
A13: size | B13: Very small; Small; Medium; Large; X-Large | C13: Qualitative size based on the description below.
A14: water_clarity | B14: Clear; Partly turbid/tannic; Turbid | C14: Qualitative water clarity based on field surveys
A15: substrate_shade | B15: Light; Medium; Dark | C15: Qualitative darkness of riverbed substrate. See Description Below.
A16: lpe_date | B16: dd-mmm | C16: Date the low-precision visual survey occurred. If no survey date could be found, the peak of spawn date range is given instead (it is assumed the visual survey occurred in this time range)
... A35: final_estimates | B35: expanded or high accuracy final estimate | C35: Expanded visual estimate, typically, lpe * 1.8; OR if there is a high accuracy method used, input that estimate.

Sheet Calibration_Input
A1: watershed_group | B1: run_timing_group | C1: CU | D1: gazetted_stream_name | E1: year | F1: system_stability | G1: size | H1: water_clarity | I1: substrate_shade | J1: number_of_est | K1: lpe_date | L1: water_discharge | M1: brightness | N1: cloud_cover | O1: fish_vis | P1: water_vis | Q1: OE | R1: interspp | S1: lpe_method | T1: peak_live_above | U1: peak_live_below | V1: live_comments | W1: ground_cuml_carc_above | X1: ground_carcs_total_above | Y1: ground_cuml_carc_below | Z1: aerial_unsexed_above | AA1: aerial_unsexed_below | AB1: carc_comments | AC1: peak_live_dead_count | AD1: estimate_method | AE1: final_estimate | AF1: RSA | AG1: RSA_reason
A2: Early Stuart | B2: Early Stuart | C2: Takla-Trembleur-Estu | D2: Driftwood River | E2: 2024 | F2: Stable | G2: Large | H2: Clear | I2: Medium | J2: 1 | K2: 45876 | M2: Full | N2: 0 | O2: High | P2: 3.0-bottom | Q2: 70 | R2: Kokanee present, mixed in with spawning SK. | S2: Aerial | T2: 2 | U2: NA | V2: Spawning areas shaded. Single survey conducted and used for estimate - timing well before peak based on other EStu systems and 100% holding (likely biased low). | W2: NA | Y2: NA | Z2: 1 | AA2: NA | AB2: 1 aerial unsexed. | AD2: =VLOOKUP(D2,prelim_final_estimates!C2:O165,13, FALSE) -> (Peak Live + Cumulative Dead)*Expansion | AE2: =VLOOKUP(D2,prelim_final_estimates!C2:H165, 6,FALSE ) -> 5 | AF2: =AE2*1.4 -> 7 | AG2: Large
A3: Early Stuart | B3: Early Stuart | C3: Takla-Trembleur-Estu | D3: Porter Creek | E3: 2024 | F3: Stable | G3: Small | H3: Clear | I3: Medium | J3: 1 | K3: 45876 | M3: Full | N3: 0 | O3: Medium | P3: 3.0-bottom | Q3: 15 | S3: Aerial | T3: 1 | U3: NA | V3: Low OE due to vegetative cover. Single survey conducted and used for estimate - timing well before peak based on other EStu systems (likely biased low). | W3: NA | Y3: NA | Z3: 0 | AA3: NA | AB3: Zero carcasses observed. | AD3: =VLOOKUP(D3,prelim_final_estimates!C3:O166,13, FALSE) -> (Peak Live + Cumulative Dead)*Expansion | AE3: =VLOOKUP(D3,prelim_final_estimates!C3:H166, 6,FALSE ) -> 2 | AF3: =AE3*1.4 -> 2.8 | AG3: High Vegetation Cover
A4: Early Stuart | B4: Early Stuart | C4: Takla-Trembleur-Estu | D4: Dust Creek | E4: 2024 | F4: Stable | G4: Small | H4: Pt. Turbid / Tannic | I4: Medium | J4: 10 | K4: 45885 | M4: Bright | N4: 50 | O4: Medium | P4: 1.0-3.0 | Q4: 65 | R4: A few 1000 Kokanee present. 300 dead Kokanee observed during peak survey. | S4: Ground | T4: 13 | U4: NA | V4: Peak live 25% spawning. | W4: 3 | X4: 8 | Y4: NA | Z4: NA | AA4: NA | AB4: Carcasses all sexed, recovered during peak live survey. | AD4: =VLOOKUP(D4,prelim_final_estimates!C4:O167,13, FALSE) -> (Peak Live + Cumulative Dead)*Expansion | AE4: =VLOOKUP(D4,prelim_final_estimates!C4:H167, 6,FALSE ) -> 26 | AF4: =AE4 -> 26 | AG4: NA
A5: Early Stuart | B5: Early Stuart | C5: Takla-Trembleur-Estu | D5: Frypan Creek | E5: 2024 | F5: Stable | G5: Small | H5: Clear | I5: Medium | J5: 10 | K5: 45887 | M5: Medium | N5: 100 | O5: High | P5: 3.0-bottom | Q5: 80 | S5: Ground | T5: 6 | U5: NA | V5: Peak live 50% spawning. | W5: 0 | Y5: NA | Z5: NA | AA5: NA | AB5: Zero recoveries. | AD5: =VLOOKUP(D5,prelim_final_estimates!C5:O168,13, FALSE) -> (Peak Live + Cumulative Dead)*Expansion | AE5: =VLOOKUP(D5,prelim_final_estimates!C5:H168, 6,FALSE ) -> 10 | AF5: =AE5 -> 10 | AG5: NA
A6: Early Stuart | B6: Early Stuart | C6: Takla-Trembleur-Estu | D6: Hudson Bay Creek | E6: 2024 | F6: Stable | G6: Small | H6: Clear | I6: Medium | J6: 10 | K6: 45885 | M6: Medium | N6: 50 | O6: High | P6: 3.0-bottom | Q6: 75 | R6: A few 100 Kokanee present. | S6: Ground | T6: 5 | U6: NA | V6: Peak live 40% spawning. | W6: 2 | X6: 5 | Y6: NA | Z6: NA | AA6: NA | AB6: Includes cumulative unsexed dead from before peak live survey due to low abundance/recovery numbers and high predation. | AD6: =VLOOKUP(D6,prelim_final_estimates!C6:O169,13, FALSE) -> (Peak Live + Cumulative Dead)*Expansion | AE6: =VLOOKUP(D6,prelim_final_estimates!C6:H169, 6,FALSE ) -> 12 | AF6: =AE6 -> 12 | AG6: NA
A7: Early Stuart | B7: Early Stuart | C7: Takla-Trembleur-Estu | D7: Narrows Creek | E7: 2024 | F7: Stable | G7: V. Small | H7: Clear | I7: Medium | J7: 10 | K7: 45885 | M7: Dark | N7: 100 | O7: Medium | P7: 3.0-bottom | Q7: 65 | R7: Kokanee present | S7: Ground | T7: 12 | U7: NA | V7: Peak live 80% spawning. | W7: 0 | Y7: NA | Z7: NA | AA7: NA | AB7: Zero recoveries. | AD7: =VLOOKUP(D7,prelim_final_estimates!C7:O170,13, FALSE) -> (Peak Live + Cumulative Dead)*Expansion | AE7: =VLOOKUP(D7,prelim_final_estimates!C7:H170, 6,FALSE ) -> 20 | AF7: =AE7 -> 20 | AG7: NA
A8: Early Stuart | B8: Early Stuart | C8: Takla-Trembleur-Estu | D8: Forfar Creek | E8: 2024 | F8: Stable | G8: V. Small | H8: Clear | I8: Medium | J8: 11 | K8: 45886 | M8: Bright | N8: 0 | O8: High | P8: 3.0-bottom | Q8: 75 | S8: Ground | T8: 14 | U8: NA | V8: Peak live 100% holding. | W8: 2 | X8: 4 | Y8: NA | Z8: NA | AA8: NA | AB8: Includes cumulative unsexed dead from before peak live survey due to low abundance/recovery numbers and high predation. | AD8: =VLOOKUP(D8,prelim_final_estimates!C8:O171,13, FALSE) -> (Peak Live + Cumulative Dead)*Expansion | AE8: =VLOOKUP(D8,prelim_final_estimates!C8:H171, 6,FALSE ) -> 27 | AF8: =AE8 -> 27 | AG8: NA
A9: Early Stuart | B9: Early Stuart | C9: Takla-Trembleur-Estu | D9: O'Ne-ell Creek | E9: 2024 | F9: Stable | G9: V. Small | H9: Clear | I9: Medium | J9: 10 | K9: 45884 | M9: Medium | N9: 75 | O9: Medium | P9: 0.5-1.0 | Q9: 60 | S9: Ground | T9: 2 | U9: NA | V9: Peak live 100% holding. | W9: 0 | Y9: NA | Z9: NA | AA9: NA | AB9: Zero recoveries. | AD9: =VLOOKUP(D9,prelim_final_estimates!C9:O172,13, FALSE) -> (Peak Live + Cumulative Dead)*Expansion | AE9: =VLOOKUP(D9,prelim_final_estimates!C9:H172, 6,FALSE ) -> 3 | AF9: =AE9 -> 3 | AG9: NA
A10: Early Stuart | B10: Early Stuart | C10: Takla-Trembleur-Estu | D10: Van Decar Creek | E10: 2024 | F10: Stable | G10: Small | H10: Clear | I10: Medium | J10: 11 | K10: 45882 | M10: Medium | N10: 100 | O10: High | P10: 3.0-bottom | Q10: 80 | S10: Ground | T10: 9 | U10: NA | W10: 2 | X10: 2 | Y10: NA | Z10: NA | AA10: NA | AB10: Two true adult recoveries from peak live survey. | AD10: =VLOOKUP(D10,prelim_final_estimates!C10:O173,13, FALSE) -> (Peak Live + Cumulative Dead)*Expansion | AE10: =VLOOKUP(D10,prelim_final_estimates!C10:H173, 6,FALSE ) -> 18 | AF10: =AE10 -> 18 | AG10: NA
A11: Early Stuart | B11: Early Stuart | C11: Takla-Trembleur-Estu | D11: Paula Creek | E11: 2024 | F11: Stable | G11: V. Small | H11: Clear | I11: Medium | J11: 7 | K11: 45886 | M11: Bright | N11: 25 | O11: High | P11: 3.0-bottom | Q11: 65 | R11: >1000 Kokanee at mouth | S11: Ground | T11: 3 | U11: NA | V11: Peak live 100% holding. | W11: 0 | Y11: NA | Z11: NA | AA11: NA | AB11: Zero recoveries. | AD11: =VLOOKUP(D11,prelim_final_estimates!C11:O174,13, FALSE) -> (Peak Live + Cumulative Dead)*Expansion | AE11: =VLOOKUP(D11,prelim_final_estimates!C11:H174, 6,FALSE ) -> 5 | AF11: =AE11 -> 5 | AG11: NA
A12: Early Stuart | B12: Early Stuart | C12: Takla-Trembleur-Estu | D12: Sidney Creek | E12: 2024 | F12: Stable | G12: Small | H12: Clear | I12: Medium | J12: 12 | K12: 45884 | M12: Medium | N12: 100 | O12: High | P12: 3.0-bottom | Q12: 70 | R12: 1000s of Kokanee in all areas up to extent. | S12: Ground | T12: 132 | U12: NA | W12: 6 | X12: 59 | Y12: NA | Z12: NA | AA12: NA | AB12: Ground cuml carc above from surveys up to and including peak live (Aug 15). Includes cumulative unsexed dead due to low abundance/recovery numbers and high predation. | AD12: =VLOOKUP(D12,prelim_final_estimates!C12:O175,13, FALSE) -> (Peak Live + Cumulative Dead)*Expansion | AE12: =VLOOKUP(D12,prelim_final_estimates!C12:H175, 6,FALSE ) -> 228 | AF12: =AE12 -> 228 | AG12: NA
A13: Early South Thompson | B13: Early Summer | C13: Shuswap-ES | D13: Eagle River | E13: 2024 | F13: Volatile | G13: Medium | H13: Pt. Turbid / Tannic | I13: Light | J13: 5 | K13: 45540 | M13: Full | N13: 0 | O13: Medium | P13: 1.0-3.0 | Q13: 50 | R13: High density of kokanee (OE comment) | S13: Ground | T13: 30 | U13: NA | W13: 1 | X13: 9 | Y13: NA | Z13: NA | AA13: NA | AB13: Ground cuml carc above includes 1 carc recovered Sep 5 during peak live survey (no carcs on first two surveys) | AD13: =VLOOKUP(D13,prelim_final_estimates!C13:O176,13, FALSE) -> (Peak Live + Cumulative Dead)*Expansion | AE13: =VLOOKUP(D13,prelim_final_estimates!C13:H176, 6,FALSE ) -> 56 | AF13: =AE13*1.3 -> 72.8 | AG13: Inconsistint Survey Schedule; Moderate Counting Conditions
A14: Early South Thompson | B14: Early Summer | C14: Shuswap-ES | D14: Seymour River | E14: 2024 | F14: Volatile | G14: Medium | H14: Clear | I14: Medium | K14: 45541 | M14: Full | N14: 0 | O14: Medium | P14: 1.0-3.0 | Q14: 70 | S14: Ground | T14: 401 | U14: NA | W14: 6 | X14: 69 | Y14: NA | Z14: NA | AA14: NA | AB14: Ground cuml carc above includes 6 carcs recovered Sep 6 during peak live survey (no carcs on first two surveys) | AD14: =VLOOKUP(D14,prelim_final_estimates!C14:O177,13, FALSE) -> (Peak Live + Cumulative Dead)*Expansion | AE14: =VLOOKUP(D14,prelim_final_estimates!C14:H177, 6,FALSE ) -> 734 | AF14: =AE14*1.3 -> 954.2 | AG14: Inconsistint Survey Schedule; Moderate Counting Conditions
A15: Early South Thompson | B15: Early Summer | C15: Shuswap - Early Summer | D15: Adams River, upper | E15: 2024 | F15: Stable | G15: Medium | H15: Turbid | I15: Light | J15: 3 | K15: 45539 | M15: Full | N15: 0 | O15: Low | P15: 0.25-0.5m | S15: Ground | T15: 0 | U15: NA | V15: No live sockeye observed. | W15: 1 | Y15: NA | Z15: NA | AA15: NA | AD15: =VLOOKUP(D15,prelim_final_estimates!C15:O178,13, FALSE) -> (Peak Live + Cumulative Dead)*Expansion | AE15: =VLOOKUP(D15,prelim_final_estimates!C15:H178, 6,FALSE ) -> 2 | AF15: =AE15*1.2 -> 2.4 | AG15: Poor Visibility
A16: Early South Thompson | B16: Early Summer | C16: Shuswap - Early Summer | D16: Anstey River | E16: 2024 | F16: Volatile | G16: Small | H16: Pt. Turbid / Tannic | I16: Medium | J16: 4 | K16: 45542 | M16: Full | N16: 0 | O16: High | P16: 3.0-bottom | Q16: 60 | R16: Possible Jacks or Kokanee, not included in totals. | S16: Ground | T16: 33 | U16: NA | W16: 1 | Y16: NA | Z16: NA | AA16: NA | AD16: =VLOOKUP(D16,prelim_final_estimates!C16:O179,13, FALSE) -> (Peak Live + Cumulative Dead)*Expansion | AE16: =VLOOKUP(D16,prelim_final_estimates!C16:H179, 6,FALSE ) -> 61 | AF16: =AE16 -> 61 | AG16: NA
A17: Early South Thompson | B17: Early Summer | C17: Shuswap - Early Summer | D17: Perry River | E17: 2024 | F17: Volatile | G17: Small | H17: Pt. Turbid / Tannic | I17: Medium | K17: 45547 | M17: Medium | N17: 100 | O17: Medium | P17: 1.0-3.0 | Q17: 55 | S17: Ground | T17: 1 | U17: NA | W17: 0 | X17: 0 | Y17: NA | Z17: NA | AA17: NA | AB17: Zero recoveries. | AD17: =VLOOKUP(D17,prelim_final_estimates!C18:O181,13, FALSE) -> (Peak Live + Cumulative Dead)*Expansion | AE17: =VLOOKUP(D17,prelim_final_estimates!C18:H181, 6,FALSE ) -> 2 | AF17: =AE17*1.2 -> 2.4 | AG17: Turbid
A18: Lower Fraser | B18: Early Summer | C18: Pitt-ES | D18: Upper Pitt River | E18: 2024 | F18: Volatile | G18: Large | H18: Clear | I18: Light | K18: 45547 | M18: Bright | N18: 100 | O18: Medium | P18: 0.5-1.0 | Q18: 60 | S18: Aerial | T18: 3434 | U18: NA | V18: Peak live above is averaged aerial counts from all areas of Upper Pitt mainstem. | W18: 724 | Y18: NA | Z18: 477 | AA18: NA | AB18: Ground cuml carc above from surveys leading up to peak live survey (191 up to Sep 11), plus 477 aerial unsexed and 56 recovered on ground in 4A side channel (533 total on Sep 12) | AD18: =VLOOKUP(D18,prelim_final_estimates!C15:O178,13, FALSE) -> (Peak Live + Cumulative Dead)*Expansion | AE18: =VLOOKUP(D18,prelim_final_estimates!C15:H178, 6,FALSE ) -> 7484 | AF18: =AE18*1.3 -> 9729.2 | AG18: Large, Turbid, Aerial
A19: Lower Fraser | B19: Early Summer | C19: Nahatlatch-ES | D19: Nahatlatch River | E19: 2024 | F19: Stable | G19: Medium | H19: Clear | I19: Medium | K19: 45537 | M19: Bright | N19: 25 | O19: High | P19: 1.0-3.0 | Q19: 60 | S19: Ground | T19: 827 | U19: NA | V19: Peak live above is live count from all areas of Nahatlatch River counted from the boat | W19: 22 | Y19: NA | Z19: NA | AA19: NA | AB19: Ground cuml carc above includes 22 carcs recovered Sep 2 during peak live survey (no carcs on first survey) | AD19: =VLOOKUP(D19,prelim_final_estimates!C16:O179,13, FALSE) -> (Peak Live + Cumulative Dead)*Expansion | AE19: =VLOOKUP(D19,prelim_final_estimates!C16:H179, 6,FALSE ) -> 1528 | AF19: =AE19*1.2 -> 1833.6 | AG19: Turbid
A20: Lower Fraser | B20: Early Summer | C20: Pitt-ES | D20: Corbold Creek | E20: 2024 | F20: Volatile | G20: Small | H20: Pt. Turbid / Tannic | I20: Medium | K20: 45540 | M20: Full | N20: 0 | O20: Medium | P20: 0.25-0.5 | Q20: 70 | S20: Ground | T20: 2105 | U20: NA | V20: Peak live count on Sep 5 (aerial count); 80% spawning, 20% spawned out. | W20: NA | Y20: NA | Z20: 75 | AA20: NA | AD20: =VLOOKUP(D20,prelim_final_estimates!C17:O180,13, FALSE) -> (Peak Live + Cumulative Dead)*Expansion | AE20: =VLOOKUP(D20,prelim_final_estimates!C17:H180, 6,FALSE ) -> 3924 | AF20: =AE20*1.02 -> 4002.48 | AG20: Turbid, Aerial
A21: Lower Fraser | B21: Early Summer | C21: Pitt-ES | D21: Fish Hatchery Creek | E21: 2024 | F21: Volatile | G21: Small | H21: Clear | I21: Medium | J21: 4 | K21: 45547 | M21: Bright | N21: 75 | O21: High | P21: 3.0-bottom | Q21: 80 | S21: Ground | T21: 6 | U21: NA | V21: Peak count Sep. 12; 100% spawning. | W21: 13 | X21: 23 | Y21: NA | Z21: NA | AA21: NA | AD21: =VLOOKUP(D21,prelim_final_estimates!C18:O181,13, FALSE) -> (Peak Live + Cumulative Dead)*Expansion | AE21: =VLOOKUP(D21,prelim_final_estimates!C18:H181, 6,FALSE ) -> 34 | AF21: =AE21 -> 34 | AG21: NA
A22: Lower Fraser | B22: Early Summer | C22: Pitt-ES | D22: South Boise Creek | E22: 2024 | F22: Volatile | G22: Small | H22: Clear | I22: Medium | J22: 3 | K22: 45541 | M22: Full | N22: 0 | O22: High | P22: 3.0-bottom | Q22: 95 | S22: Ground | T22: 45 | U22: NA | V22: Peak live count Sep. 13; 100% spawning. | W22: 6 | Y22: NA | Z22: NA | AA22: NA | AD22: =VLOOKUP(D22,prelim_final_estimates!C19:O182,13, FALSE) -> (Peak Live + Cumulative Dead)*Expansion | AE22: =VLOOKUP(D22,prelim_final_estimates!C19:H182, 6,FALSE ) -> 92 | AF22: =AE22 -> 92 | AG22: NA
A23: Lower Fraser | B23: Early Summer | C23: Pitt-ES | D23: Olsen Creek | E23: 2024 | F23: Volatile | G23: Small | H23: Clear | I23: Medium | J23: 2 | K23: 45548 | M23: Medium | N23: 100 | O23: High | P23: 3.0-bottom | Q23: 80 | S23: Ground | T23: 5 | U23: NA | V23: Peak live count Sep. 13; 80% spawning, 20% spawned out. | W23: 3 | Y23: NA | Z23: NA | AA23: NA | AD23: =VLOOKUP(D23,prelim_final_estimates!C20:O183,13, FALSE) -> (Peak Live + Cumulative Dead)*Expansion | AE23: =VLOOKUP(D23,prelim_final_estimates!C20:H183, 6,FALSE ) -> 14 | AF23: =AE23 -> 14 | AG23: NA
A24: Lower Fraser | B24: Early Summer | C24: Pitt-ES | D24: Upper Pitt Channel | E24: 2024 | F24: Volatile | G24: Small | H24: Pt. Turbid / Tannic | I24: Medium | J24: 4 | K24: 45540 | M24: Full | N24: 0 | O24: Medium | P24: 0.5-1.0 | Q24: 70 | S24: Ground | T24: 1711 | U24: NA | V24: Peak live count Sep. 5; 100% spawning. | W24: 47 | X24: 537 | Y24: NA | Z24: NA | AA24: NA | AD24: =VLOOKUP(D24,prelim_final_estimates!C21:O184,13, FALSE) -> (Peak Live + Cumulative Dead)*Expansion | AE24: =VLOOKUP(D24,prelim_final_estimates!C21:H184, 6,FALSE ) -> 3164 | AF24: =AE24 -> 3164 | AG24: NA
A25: Lower Fraser | B25: Early Summer | C25: Chilliwack-ES | D25: Depot Creek | E25: 2024 | F25: Volatile | G25: Small | H25: Pt. Turbid / Tannic | I25: Medium | J25: 5 | K25: 45532 | M25: Full | N25: 0 | O25: High | P25: 1.0-3.0 | Q25: 69 | S25: Ground | T25: 26 | U25: NA | V25: Peak live count Aug. 28; 80% holding, 20% spawning. | W25: 5 | X25: 6 | Y25: NA | Z25: NA | AA25: NA | AD25: =VLOOKUP(D25,prelim_final_estimates!C22:O185,13, FALSE) -> (Peak Live + Cumulative Dead)*Expansion | AE25: =VLOOKUP(D25,prelim_final_estimates!C22:H185, 6,FALSE ) -> 56 | AF25: =AE25 -> 56 | AG25: NA
A26: Lower Fraser | B26: Early Summer | C26: Chilliwack-ES | D26: Paleface Creek | E26: 2024 | F26: Volatile | G26: Small | H26: Clear | I26: Medium | J26: 5 | K26: 45532 | M26: Full | N26: 0 | O26: High | P26: 3.0-bottom | Q26: 80 | R26: Approx 50 Kokanee in first 100m. | S26: Ground | T26: 3 | U26: NA | V26: Peak live count Aug. 28; 65% holding, 35% spawning. | W26: 1 | X26: 2 | Y26: NA | Z26: NA | AA26: NA | AD26: =VLOOKUP(D26,prelim_final_estimates!C23:O186,13, FALSE) -> (Peak Live + Cumulative Dead)*Expansion | AE26: =VLOOKUP(D26,prelim_final_estimates!C23:H186, 6,FALSE ) -> 7 | AF26: =AE26 -> 7 | AG26: NA
A27: Seton-Anderson | B27: Early Summer | C27: Anderson-Seton - Early Summer | D27: Gates River | E27: 2024 | F27: Stable | G27: V. Small | H27: Turbid | I27: Medium | J27: 5 | K27: 45535 | M27: Full | N27: 0 | O27: Low | P27: 0.5-1.0 | Q27: 57 | S27: Ground | T27: 2525 | U27: NA | V27: Peak live count on Aug 31 & Sep 1; 30-80% spawning. | W27: 108 | X27: 1348 | Y27: NA | Z27: NA | AA27: NA | AD27: =VLOOKUP(D27,prelim_final_estimates!C24:O187,13, FALSE) -> (Peak Live + Cumulative Dead)*Expansion | AE27: =VLOOKUP(D27,prelim_final_estimates!C24:H187, 6,FALSE ) -> 5481 | AF27: =AE27*1.2 -> 6577.2 | AG27: Turbid
A28: Seton-Anderson | B28: Early Summer | C28: Anderson-Seton - Early Summer | D28: Haylmore Creek | E28: 2024 | F28: Volatile | G28: V. Small | H28: Turbid | I28: Medium | J28: 5 | K28: 45536 | M28: Full | N28: 0 | O28: High | P28: 3.0-bottom | Q28: 70 | S28: Ground | T28: 84 | U28: NA | V28: Peak live count on Sep 1; 50% spawning. | W28: 0 | X28: 10 | Y28: NA | Z28: NA | AA28: NA | AD28: =VLOOKUP(D28,prelim_final_estimates!C25:O188,13, FALSE) -> (Peak Live + Cumulative Dead)*Expansion | AE28: =VLOOKUP(D28,prelim_final_estimates!C25:H188, 6,FALSE ) -> 151 | AF28: =AE28*1.2 -> 181.2 | AG28: Turbid
A29: Seton-Anderson | B29: Early Summer | C29: Anderson-Seton - Early Summer | D29: Spruce Creek | E29: 2024 | F29: Volatile | G29: V. Small | H29: Turbid | I29: Medium | J29: 4 | K29: 45535 | M29: Full | N29: 0 | O29: High | P29: 3.0-bottom | Q29: 85 | S29: Ground | T29: 3 | U29: NA | W29: 0 | X29: 0 | Y29: NA | Z29: NA | AA29: NA | AB29: Zero recoveries. | AD29: =VLOOKUP(D29,prelim_final_estimates!C26:O189,13, FALSE) -> (Peak Live + Cumulative Dead)*Expansion | AE29: =VLOOKUP(D29,prelim_final_estimates!C26:H189, 6,FALSE ) -> 5 | AF29: =AE29*1.2 -> 6 | AG29: Turbid
A30: Nechako | B30: Early Summer | C30: Nadina-Francois-ES | D30: Late Nadina River | E30: 2024 | F30: Stable | G30: Medium | H30: Pt. Turbid / Tannic | I30: Dark | K30: 45919 | M30: Medium | N30: 75 | O30: High | P30: 1.0-3.0 | Q30: 69.166667 | S30: Aerial | T30: 37657.5 | U30: 580 | V30: Peak live above is areas 3-6 (from 2nd bridge to Nadina Lk). Peak live below is areas 1-2 (mouth to 2nd bridge) - mouth excluded (50 fish). Live count is average of two observers. | W30: 1244 | Y30: NA | Z30: 958 | AA30: 5 | AB30: Ground cuml carc from surveys leading up to peak live survey, not including unsexed dead from ground. Aerial carc count from obs 1 only - obs 2 counts only available for two areas and don't see reliable. | AD30: =VLOOKUP(D30,prelim_final_estimates!C27:O190,13, FALSE) -> DIDSON/ARIS counter | AE30: =VLOOKUP(D30,prelim_final_estimates!C24:H187, 6,FALSE ) -> 89321 | AF30: =AE30 -> 89321 | AG30: NA
A31: North Thompson | B31: Early Summer | C31: North Barriere - ES | D31: Barriere River, upper | E31: 2024 | F31: Stable | G31: V. Small | H31: Clear | I31: Medium | J31: 5 | K31: 45537 | M31: Bright | N31: 100 | O31: High | P31: 3.0-bottom | Q31: 65 | S31: Ground | T31: 1001 | U31: NA | W31: 58 | X31: 328 | Y31: NA | Z31: NA | AA31: NA | AB31: Ground cuml carc above includes 58 carcs recovered Sep 2 during peak live survey (no carcs on first survey) | AD31: =VLOOKUP(D31,prelim_final_estimates!C28:O191,13, FALSE) -> (Peak Live + Cumulative Dead)*Expansion | AE31: =VLOOKUP(D31,prelim_final_estimates!C25:H188, 6,FALSE ) -> 1906 | AF31: =AE31 -> 1906 | AG31: NA
A32: Upper Fraser | B32: Early Summer | C32: Bowron-ES | D32: Bowron River, upper | E32: 2024 | F32: Stable | G32: Medium | H32: Clear | I32: Medium | J32: 2 | K32: 45544 | M32: Full | N32: 0 | O32: High | P32: 3.0-bottom | Q32: 70 | S32: Aerial | T32: 215 | U32: NA | V32: Peak live 100% spawning, but protracted spawning observed over 3 weeks. Peak count likely after peak spawning. | W32: NA | Y32: NA | Z32: 5 | AA32: NA | AB32: Ground surveys conducted after peak live survey. | AD32: =VLOOKUP(D32,prelim_final_estimates!C29:O192,13, FALSE) -> (Peak Live + Cumulative Dead)*Expansion | AE32: =VLOOKUP(D32,prelim_final_estimates!C26:H189, 6,FALSE ) -> 616 | AF32: =AE32 -> 616 | AG32: NA
A33: Late Stuart | B33: Summer | C33: Takla-Trembleur-Stuart-S | D33: Kazchek Creek | E33: 2024 | F33: Stable | G33: Small | H33: Clear | I33: Medium | J33: 7 | K33: 45555 | M33: Full | N33: 50 | O33: High | P33: 3.0-bottom | Q33: 76 | S33: Ground | T33: 49 | U33: NA | V33: Same live count on back to back surveys; first majority holding; second 90% spawning. | W33: 0 | Y33: NA | Z33: NA | AA33: NA | AB33: Zero recoveries. | AD33: =VLOOKUP(D33,prelim_final_estimates!C34:O197,13, FALSE) -> (Peak Live + Cumulative Dead)*Expansion | AE33: =VLOOKUP(D33,prelim_final_estimates!C31:H194, 6,FALSE ) -> 88 | AF33: =AE33 -> 88 | AG33: NA
A34: Late Stuart | B34: Summer | C34: Takla-Trembleur-Stuart-S | D34: Kuzkwa Creek | E34: 2024 | F34: Stable | G34: Medium | H34: Clear | I34: Medium | J34: 9 | K34: 45553 | M34: Medium | N34: 75 | O34: High | P34: 1.0-3.0 | Q34: 80 | S34: Ground | T34: 1614 | U34: NA | V34: Peak live count from peak live ground survey of A1 (Sep. 18) and aerial live count of A2 (Sep. 25). POS lines up better with peak ground survey but no aerial survey until Sep. 25. Environmentals are from Sep 18 when greater proportion of peak counted. | W34: 22 | Y34: NA | Z34: 3 | AA34: NA | AB34: Cumulative carcasses used for estimate = 25. 22 sexed carcasses from ground surveys, 3 unsexed carcasses from aerial survey. | AD34: =VLOOKUP(D34,prelim_final_estimates!C35:O198,13, FALSE) -> (Peak Live + Cumulative Dead)*Expansion | AE34: =VLOOKUP(D34,prelim_final_estimates!C32:H195, 6,FALSE ) -> 2950 | AF34: =AE34*1.3 -> 3835 | AG34: Tannic, Aerial, Survey Schedule
A35: Late Stuart | B35: Summer | C35: Takla-Trembleur-Stuart-S | D35: Middle River | E35: 2024 | F35: Volatile | G35: X-Large | H35: Pt. Turbid / Tannic | I35: Medium | J35: 10 | K35: 45560 | M35: Bright | N35: 75 | O35: High | P35: 1.0-3.0 | Q35: 81.25 | S35: Aerial | T35: 8080 | U35: NA | V35: Peak live aerial from one observer. Observer 2 count 38% difference. | W35: 50 | Y35: NA | Z35: 30 | AA35: NA | AB35: Cumulative carcasses used for estimate = 80. 50 sexed recovered on ground leading up to peak survey. 30 unsexed observed during aerial. | AD35: =VLOOKUP(D35,prelim_final_estimates!C36:O199,13, FALSE) -> (Peak Live + Cumulative Dead)*Expansion | AE35: =VLOOKUP(D35,prelim_final_estimates!C33:H196, 6,FALSE ) -> 14688 | AF35: =AE35*1.3 -> 19094.4 | AG35: X-Large, Tannic, Aerial
A36: Late Stuart | B36: Summer | C36: Takla-Trembleur-Stuart-S | D36: Pinchi Creek | E36: 2024 | F36: Stable | G36: Small | H36: Clear | I36: Medium | J36: 10 | K36: 45560 | M36: Medium | N36: 100 | O36: Medium | P36: 0.25-0.5 | Q36: 74.17 | S36: Ground | T36: 359 | U36: NA | V36: Peak live 85% spawning. Good visibility in some areas and very poor in others. Very low water in some areas as well. | W36: 11 | X36: 36 | Y36: NA | Z36: NA | AA36: NA | AB36: Predation made recovery very difficult. | AD36: =VLOOKUP(D36,prelim_final_estimates!C37:O200,13, FALSE) -> (Peak Live + Cumulative Dead)*Expansion | AE36: =VLOOKUP(D36,prelim_final_estimates!C34:H197, 6,FALSE ) -> 666 | AF36: =AE36 -> 666 | AG36: NA
A37: Late Stuart | B37: Summer | C37: Takla-Trembleur-Stuart-S | D37: Tachie River | E37: 2024 | F37: Volatile | G37: X-Large | H37: Pt. Turbid / Tannic | I37: Dark | J37: 10 | K37: 45560 | M37: Medium | N37: 100 | O37: Medium | P37: 0.5-1.0 | Q37: 61.67 | S37: Aerial | T37: 15619 | U37: NA | V37: Peak live 100% spawning. Fish visibility variable. Tannic water and rain made it difficult to count deeper fish. | W37: 13 | X37: 1278 | Y37: NA | Z37: 3 | AA37: NA | AB37: Cumulative carcasses used for estimate = 16. 13 sexed recovered during ground surveys leading up to peak aerial. 3 unsexed observed during aerial. | AD37: =VLOOKUP(D37,prelim_final_estimates!C38:O201,13, FALSE) -> (Peak Live + Cumulative Dead)*Expansion | AE37: =VLOOKUP(D37,prelim_final_estimates!C35:H198, 6,FALSE ) -> 28143 | AF37: =AE37*1.4 -> 39400.2 | AG37: X-Large, Tannic, Aerial, Deep
A38: Nechako | B38: Summer | C38: Francois-Fraser-S | D38: Stellako River | E38: 2024 | F38: Stable | G38: Medium | H38: Clear | I38: Medium | K38: 45561 | M38: Bright | N38: 75 | O38: Medium | P38: 1.0-3.0 | Q38: 80 | S38: Ground | T38: 48787 | U38: NA | V38: Peak live above the fence is areas 1-9. Peak live below the fence is area 10 (not surveyed). Live count is from one observer. | W38: 6 | Y38: NA | Z38: NA | AA38: NA | AB38: No carcasses counted during ground survey, live count only. Ground cumulative above comes from recovery surveys up until the day before the peak live survey. | AD38: =VLOOKUP(D38,prelim_final_estimates!C39:O202,13, FALSE) -> DIDSON/ARIS counter | AE38: =VLOOKUP(D38,prelim_final_estimates!C36:H199, 6,FALSE ) -> 65165 | AF38: =AE38 -> 65165 | AG38: NA
A39: North Thompson | B39: Summer | C39: Kamloops-ES | D39: Raft River | E39: 2024 | F39: Stable | G39: Medium | H39: Clear | I39: Medium | J39: 6 | K39: 45545 | M39: Bright | N39: 25 | O39: High | P39: 1.0-3.0 | Q39: 70 | S39: Ground | T39: 5601 | U39: NA | W39: 1544 | X39: 3616 | Y39: NA | Z39: NA | AA39: NA | AD39: =VLOOKUP(D39,prelim_final_estimates!C40:O203,13, FALSE) -> (Peak Live + Cumulative Dead)*Expansion | AE39: =VLOOKUP(D39,prelim_final_estimates!C37:H200, 6,FALSE ) -> 12861 | AF39: =AE39*1.2 -> 15433.2 | AG39: Medium, Evidence from Prior Calibration Point
A40: Quesnel | B40: Summer | C40: Cariboo-S | D40: Cariboo River, upper | E40: 2024 | F40: Stable | G40: Large | H40: Turbid | I40: Light | J40: 3 | K40: 45553 | M40: Full | N40: 0 | O40: Medium | S40: Aerial | T40: 570 | U40: NA | V40: Peak live 100% spawning/spawned out. All fish observed in side channel (A3). Small group of fish spawning in mainstem observed during first survey. | W40: 2 | Y40: NA | Z40: 0 | AA40: NA | AB40: 12 unsexed carcasses observed during first aerial survey. Not included in estimate. | AD40: =VLOOKUP(D40,prelim_final_estimates!C41:O204,13, FALSE) -> (Peak Live + Cumulative Dead)*Expansion | AE40: =VLOOKUP(D40,prelim_final_estimates!C38:H201, 6,FALSE ) -> 1030 | AF40: =AE40*1.5 -> 1545 | AG40: Large, Turbid, Survey Schedule
...

Sheet prelim_final_estimates
A1: Year | B1: Watershed Group Name | C1: Stock Name(stream) | D1: Timing Group | E1: CU Name | F1: spnpeak | G1: arrival | H1: Total | I1: jacks | J1: males | K1: females | L1: spawn% | M1: eff_fem | N1: remarks | O1: Estimate Method | P1: Survey Start | Q1: Survey End | R1: Number Inspections | S1: est_type | T1: Forecast
A2: 2024 | B2: Early Stuart | C2: Driftwood River | D2: T1 | E2: Takla-Trembleur - Early Stuart | H2: 5 | I2: 5 | J2: 0 | K2: 0 | L2: 84.5 | M2: 0 | N2: One aerial survey conducted. Takla-Trembleur-Early Stuart composite sex ratio and twenty-year average (2004-2023) spawn success applied. | O2: (Peak Live + Cumulative Dead)*Expansion | P2: 45511 | Q2: 45511 | R2: 1 | S2: Type-4: Relative Abundance, medium resolution | T2: 1
A3: 2024 | B3: Early Stuart | C3: Kotsine River | D3: T1 | E3: Takla-Trembleur - Early Stuart | H3: 0 | I3: 0 | J3: 0 | K3: 0 | L3: 0 | M3: 0 | N3: One aerial survey conducted. No live or dead sockeye observed. | O3: (Peak Live + Cumulative Dead)*Expansion | P3: 45511 | Q3: 45511 | R3: 1 | S3: Type-4: Relative Abundance, medium resolution | T3: 1
A4: 2024 | B4: Early Stuart | C4: Porter Creek | D4: T1 | E4: Takla-Trembleur - Early Stuart | H4: 2 | I4: 2 | J4: 0 | K4: 0 | L4: 84.5 | M4: 0 | N4: One aerial survey conducted. Takla-Trembleur-Early Stuart composite sex ratio and twenty-year average (2004-2023) spawn success applied. | O4: (Peak Live + Cumulative Dead)*Expansion | P4: 45511 | Q4: 45511 | R4: 1 | S4: Type-4: Relative Abundance, medium resolution | T4: 1
A5: 2024 | B5: Early Stuart | C5: Crow Creek | D5: T1 | E5: Takla-Trembleur - Early Stuart | H5: 0 | I5: 0 | J5: 0 | K5: 0 | L5: 0 | M5: 0 | N5: Six ground surveys conducted; no sockeye observed. | O5: (Peak Live + Cumulative Dead)*Expansion | P5: 45496 | Q5: 45516 | R5: 6 | S5: Type-3: Relative Abundance, high resolution | T5: 1
A6: 2024 | B6: Early Stuart | C6: Dust Creek | D6: T1 | E6: Takla-Trembleur - Early Stuart | F6: Aug. 16-21, 2024 | G6: Early August | H6: 26 | I6: 24 | J6: 1 | K6: 1 | L6: 84.5 | M6: 1 | N6: Ten ground surveys conducted. High predation. Takla-Trembleur-Early Stuart composite sex ratio and twenty-year average (2004-2023) spawn success applied. | O6: (Peak Live + Cumulative Dead)*Expansion | P6: 45496 | Q6: 45524 | R6: 10 | S6: Type-3: Relative Abundance, high resolution | T6: 1
A7: 2024 | B7: Early Stuart | C7: Hooker Creek | D7: T1 | E7: Takla-Trembleur - Early Stuart | H7: 0 | I7: 0 | J7: 0 | K7: 0 | L7: 0 | M7: 0 | N7: Six ground surveys conducted. No sockeye observed. | O7: (Peak Live + Cumulative Dead)*Expansion | P7: 45496 | Q7: 45516 | R7: 6 | S7: Type-3: Relative Abundance, high resolution | T7: 1
A8: 2024 | B8: Early Stuart | C8: Point Creek | D8: T1 | E8: Takla-Trembleur - Early Stuart | H8: 0 | I8: 0 | J8: 0 | K8: 0 | L8: 0 | M8: 0 | N8: Six ground surveys conducted; no sockeye observed. | O8: (Peak Live + Cumulative Dead)*Expansion | P8: 45496 | Q8: 45634 | R8: 6 | S8: Type-3: Relative Abundance, high resolution | T8: 1
A9: 2024 | B9: Early Stuart | C9: Sinta Creek | D9: T1 | E9: Takla-Trembleur - Early Stuart | H9: 0 | I9: 0 | J9: 0 | K9: 0 | L9: 0 | M9: 0 | N9: Five ground surveys conducted; no sockeye observed. | O9: (Peak Live + Cumulative Dead)*Expansion | P9: 45496 | Q9: 45512 | R9: 5 | S9: Type-3: Relative Abundance, high resolution | T9: 1
A10: 2024 | B10: Early Stuart | C10: Ankwill Creek | D10: T1 | E10: Takla-Trembleur - Early Stuart | H10: 0 | I10: 0 | J10: 0 | K10: 0 | L10: 0 | M10: 0 | N10: Two ground surveys conducted; no sockeye observed. | O10: (Peak Live + Cumulative Dead)*Expansion | P10: 45504 | Q10: 45508 | R10: 2 | S10: Type-4: Relative Abundance, medium resolution | T10: 1
A11: 2024 | B11: Early Stuart | C11: Blanchet Creek | D11: T1 | E11: Takla-Trembleur - Early Stuart | H11: 0 | I11: 0 | J11: 0 | K11: 0 | L11: 0 | M11: 0 | N11: Six ground surveys conducted; no sockeye observed. | O11: (Peak Live + Cumulative Dead)*Expansion | P11: 45495 | Q11: 45515 | R11: 6 | S11: Type-3: Relative Abundance, high resolution | T11: 1
A12: 2024 | B12: Early Stuart | C12: Blanchet North Creek | D12: T1 | E12: Takla-Trembleur - Early Stuart | H12: 0 | I12: 0 | J12: 0 | K12: 0 | L12: 0 | M12: 0 | N12: Six ground surveys conducted; no sockeye observed. | O12: (Peak Live + Cumulative Dead)*Expansion | P12: 45495 | Q12: 45515 | R12: 6 | S12: Type-3: Relative Abundance, high resolution | T12: 1
A13: 2024 | B13: Early Stuart | C13: 15 Mile Creek | D13: T1 | E13: Takla-Trembleur - Early Stuart | H13: 0 | I13: 0 | J13: 0 | K13: 0 | L13: 0 | M13: 0 | N13: Six ground surveys conducted; no sockeye observed. | O13: (Peak Live + Cumulative Dead)*Expansion | P13: 45495 | Q13: 45515 | R13: 6 | S13: Type-3: Relative Abundance, high resolution | T13: 1
A14: 2024 | B14: Early Stuart | C14: 25 Mile Creek | D14: T1 | E14: Takla-Trembleur - Early Stuart | H14: 0 | I14: 0 | J14: 0 | K14: 0 | L14: 0 | M14: 0 | N14: Six ground surveys conducted; no sockeye observed. | O14: (Peak Live + Cumulative Dead)*Expansion | P14: 45495 | Q14: 45515 | R14: 6 | S14: Type-3: Relative Abundance, high resolution | T14: 1
A15: 2024 | B15: Early Stuart | C15: Frypan Creek | D15: T1 | E15: Takla-Trembleur - Early Stuart | F15: Aug. 16-21, 2024 | H15: 10 | I15: 8 | J15: 1 | K15: 1 | L15: 84.5 | M15: 1 | N15: Ten ground surveys conducted. 1990-2009 system average cycle index applied. Takla-Trembleur-Early Stuart composite sex ratio and 20-year average (2004-2023) spawn success applied. | O15: (Peak Live + Cumulative Dead)*Expansion | P15: 45495 | Q15: 45524 | R15: 10 | S15: Type-4: Relative Abundance, medium resolution | T15: 1
A16: 2024 | B16: Early Stuart | C16: Hudson Bay Creek | D16: T1 | E16: Takla-Trembleur - Early Stuart | F16: Aug. 15-20, 2024 | H16: 12 | I16: 10 | J16: 1 | K16: 1 | L16: 84.5 | M16: 1 | N16: Ten ground surveys conducted. System average (1990-2009) 4 day cycle index applied.Takla-Trembleur-EStu composite sex ratio and 20-year average (2004-2023) spawn success applied. | O16: (Peak Live + Cumulative Dead)*Expansion | P16: 45495 | Q16: 45524 | R16: 10 | S16: Type-3: Relative Abundance, high resolution | T16: 1
A17: 2024 | B17: Early Stuart | C17: Lovell Creek | D17: T1 | E17: Takla-Trembleur - Early Stuart | H17: 0 | I17: 0 | J17: 0 | K17: 0 | L17: 0 | M17: 0 | N17: Six rgound surveys conducted; no sockeye observed. | O17: (Peak Live + Cumulative Dead)*Expansion | P17: 45495 | Q17: 45515 | R17: 6 | S17: Type-3: Relative Abundance, high resolution | T17: 1
A18: 2024 | B18: Early Stuart | C18: Maclaing Creek | D18: T1 | E18: Takla-Trembleur - Early Stuart | H18: 0 | I18: 0 | J18: 0 | K18: 0 | L18: 0 | M18: 0 | N18: Six ground surveys conducted; no sockeye observed. | O18: (Peak Live + Cumulative Dead)*Expansion | P18: 45495 | Q18: 45515 | R18: 6 | S18: Type-4: Relative Abundance, medium resolution | T18: 1
A19: 2024 | B19: Early Stuart | C19: Shale Creek | D19: T1 | E19: Takla-Trembleur - Early Stuart | H19: 0 | I19: 0 | J19: 0 | K19: 0 | L19: 0 | M19: 0 | N19: Six ground surveys conducted; no sockeye observed. | O19: (Peak Live + Cumulative Dead)*Expansion | P19: 45495 | Q19: 45515 | R19: 6 | S19: Type-3: Relative Abundance, high resolution | T19: 1
A20: 2024 | B20: Early Stuart | C20: Tliti Creek | D20: T1 | E20: Takla-Trembleur - Early Stuart | H20: 0 | I20: 0 | J20: 0 | K20: 0 | L20: 0 | M20: 0 | N20: Six ground surveys conducted; no sockeye observed. | O20: (Peak Live + Cumulative Dead)*Expansion | P20: 45495 | Q20: 45518 | R20: 6 | S20: Type-3: Relative Abundance, high resolution | T20: 1
A21: 2024 | B21: Early Stuart | C21: Bivouac Creek | D21: T1 | E21: Takla-Trembleur - Early Stuart | H21: 0 | I21: 0 | J21: 0 | K21: 0 | L21: 0 | M21: 0 | N21: Five ground surveys conducted; no sockeye observed. | O21: (Peak Live + Cumulative Dead)*Expansion | P21: 45495 | Q21: 45511 | R21: 5 | S21: Type-3: Relative Abundance, high resolution | T21: 1
A22: 2024 | B22: Early Stuart | C22: Gluske Creek | D22: T1 | E22: Takla-Trembleur - Early Stuart | H22: 0 | I22: 0 | J22: 0 | K22: 0 | L22: 0 | M22: 0 | N22: One ground survey of mouth conducted; no sockeye observed. Large beaver dam. Surveys halted due to safety concerns. | O22: (Peak Live + Cumulative Dead)*Expansion | P22: 45497 | Q22: 45497 | R22: 1 | S22: Type-5: Relative Abundance, low resolution | T22: 1
A23: 2024 | B23: Early Stuart | C23: Leo Creek | D23: T1 | E23: Takla-Trembleur - Early Stuart | H23: 0 | I23: 0 | J23: 0 | K23: 0 | L23: 0 | M23: 0 | N23: Six ground surveys conducted; no sockeye observed. | O23: (Peak Live + Cumulative Dead)*Expansion | P23: 45494 | Q23: 45514 | R23: 6 | S23: Type-3: Relative Abundance, high resolution | T23: 1
A24: 2024 | B24: Early Stuart | C24: Narrows Creek | D24: T1 | E24: Takla-Trembleur - Early Stuart | F24: Aug. 15-20, 2024 | H24: 20 | I24: 18 | J24: 1 | K24: 1 | L24: 84.5 | M24: 1 | N24: Ten ground surveys conducted. System average (1990-2009) cycle index applied. Takla-Trembleur-Early Stuat composite sex ratio and 20-year average (2004-2023) spawn success applied. | O24: (Peak Live + Cumulative Dead)*Expansion | P24: 45496 | Q24: 45524 | R24: 10 | S24: Type-3: Relative Abundance, high resolution | T24: 1
A25: 2024 | B25: Early Stuart | C25: Sakeniche River | D25: T1 | E25: Takla-Trembleur - Early Stuart | H25: 0 | I25: 0 | J25: 0 | K25: 0 | L25: 0 | M25: 0 | N25: Five ground surveys conducted; no sockeye observed. | O25: (Peak Live + Cumulative Dead)*Expansion | P25: 45495 | Q25: 45511 | R25: 5 | S25: Type-3: Relative Abundance, high resolution | T25: 1
A26: 2024 | B26: Early Stuart | C26: Sandpoint Creek | D26: T1 | E26: Takla-Trembleur - Early Stuart | H26: 0 | I26: 0 | J26: 0 | K26: 0 | L26: 0 | M26: 0 | N26: Five ground surveys; no sockeye observed. | O26: (Peak Live + Cumulative Dead)*Expansion | P26: 45495 | Q26: 45511 | R26: 5 | S26: Type-3: Relative Abundance, high resolution | T26: 1
A27: 2024 | B27: Early Stuart | C27: Baptiste Creek | D27: T1 | E27: Takla-Trembleur - Early Stuart | H27: 0 | I27: 0 | J27: 0 | K27: 0 | L27: 0 | M27: 0 | N27: Five ground surveys conducted; no sockeye observed.. | O27: (Peak Live + Cumulative Dead)*Expansion | P27: 45494 | Q27: 45510 | R27: 5 | S27: Type-3: Relative Abundance, high resolution | T27: 1
A28: 2024 | B28: Early Stuart | C28: Forfar Creek | D28: T1 | E28: Takla-Trembleur - Early Stuart | F28: Aug. 17-22, 2024 | H28: 27 | I28: 25 | J28: 1 | K28: 1 | L28: 84.5 | M28: 1 | N28: Eleven ground surveys conducted. Forfar Creek average index applied. Takla-Trembleur-Early Stuart composite sex ratio and 20-year average (2004-2023) spawn success applied. | O28: (Peak Live + Cumulative Dead)*Expansion | P28: 45493 | Q28: 45525 | R28: 11 | S28: Type-3: Relative Abundance, high resolution | T28: 1
A29: 2024 | B29: Early Stuart | C29: Kazchek Creek | D29: T1 | E29: Takla-Trembleur - Early Stuart | H29: 0 | I29: 0 | J29: 0 | K29: 0 | L29: 0 | M29: 0 | N29: Six ground surveys conducted; no sockeye observed. | O29: (Peak Live + Cumulative Dead)*Expansion | P29: 45494 | Q29: 45514 | R29: 6 | S29: Type-3: Relative Abundance, high resolution | T29: 1
A30: 2024 | B30: Early Stuart | C30: Middle River (Rossette Bar) | D30: T1 | E30: Takla-Trembleur - Early Stuart | H30: 0 | I30: 0 | J30: 0 | K30: 0 | L30: 0 | M30: 0 | N30: Six ground surveys conducted; no sockeye observed. | O30: (Peak Live + Cumulative Dead)*Expansion | P30: 45494 | Q30: 45523 | R30: 6 | S30: Type-3: Relative Abundance, high resolution | T30: 1
A31: 2024 | B31: Early Stuart | C31: O'Ne-ell Creek | D31: T1 | E31: Takla-Trembleur - Early Stuart | H31: 3 | I31: 3 | J31: 0 | K31: 0 | L31: 0 | M31: 0 | N31: Ten ground surveys conducted. O'Ne-Ell Creek average index applied. Takla-Trembleur-Early Stuart composite sex ratio and 20-year average (2004-2023) spawn success applied | O31: (Peak Live + Cumulative Dead)*Expansion | P31: 45493 | Q31: 45523 | R31: 10 | S31: Type-3: Relative Abundance, high resolution | T31: 1
A32: 2024 | B32: Early Stuart | C32: Van Decar Creek | D32: T1 | E32: Takla-Trembleur - Early Stuart | F32: Aug. 14-19, 2024 | H32: 18 | I32: 16 | J32: 1 | K32: 1 | L32: 84.5 | M32: 1 | N32: Eleven ground surveys conducted. Brood stock fence observed Aug. 13-17th. System average (1990-2009) 4 day cycle index applied.Takla-Trembleur-EStu composite sex ratio and 20-year average (2004-2023) spawn success applied. | O32: (Peak Live + Cumulative Dead)*Expansion | P32: 45493 | Q32: 45525 | R32: 11 | S32: Type-3: Relative Abundance, high resolution | T32: 1
A33: 2024 | B33: Early Stuart | C33: Paula Creek | D33: T1 | E33: Takla-Trembleur - Early Stuart | H33: 5 | I33: 5 | J33: 0 | K33: 0 | L33: 84.5 | M33: 0 | N33: Seven ground surveys conducted. System average (1990-2009) 4 day cycle index applied. Takla-Trembleur-Early Stuart composite sex ratio and 20-year average (2004-2023) spawn success applied. | O33: (Peak Live + Cumulative Dead)*Expansion | P33: 45494 | Q33: 45521 | R33: 7 | S33: Type-3: Relative Abundance, high resolution | T33: 1
A34: 2024 | B34: Early Stuart | C34: Sidney Creek | D34: T1 | E34: Takla-Trembleur - Early Stuart | F34: Aug. 15-20,2024 | H34: 228 | I34: 214 | J34: 0 | K34: 14 | L34: 84.5 | M34: 12 | N34: Twelve ground surveys conducted. Predation prevalent. System average (1990-2009) 4 day cycle index applied. Takla-Trembleur-Early Stuart 20-year average (2004-2023) spawn success applied. | O34: (Peak Live + Cumulative Dead)*Expansion | P34: 45494 | Q34: 45528 | R34: 12 | S34: Type-3: Relative Abundance, high resolution | T34: 1
A35: 2024 | B35: Lower Fraser | C35: Chilliwack Lake | D35: T2 | E35: Chilliwack - Early Summer | H35: 153 | I35: 0 | J35: 56 | K35: 97 | L35: 77.27 | M35: 75 | N35: Three ground surveys conducted. Population estimate based on IPSFC recovery/effort expansion. Chilliwack-ES composite sex ratio and success of spawn applied. | O35: Lake Expansion | P35: 45524 | Q35: 45542 | R35: 3 | S35: Type-3: Relative Abundance, high resolution | T35: 23
A36: 2024 | B36: Lower Fraser | C36: Chilliwack River, upper | D36: T2 | E36: Chilliwack - Early Summer | F36: Sep. 17-25, 2024 | H36: 26036 | I36: 0 | J36: 9465 | K36: 16571 | L36: 77.3 | M36: 12809 | N36: SONAR operational Jul. 10 to Sep. 9. 1.1% of estimate extrapolated. | O36: DIDSON/ARIS counter | P36: 45483 | Q36: 45544 | R36: 57 | S36: Type-2: True Abundance, medium resolution | T36: 23
A37: 2024 | B37: Lower Fraser | C37: Depot Creek | D37: T2 | E37: Chilliwack - Early Summer | F37: Aug. 30 - Sep. 5, 2024 | H37: 56 | I37: 0 | J37: 20 | K37: 36 | L37: 77.27 | M37: 28 | N37: Five ground surveys conducted. Chilliwack-ES composite sex ratio and spawn success applied. | O37: (Peak Live + Cumulative Dead)*Expansion | P37: 45512 | Q37: 45519 | R37: 5 | S37: Type-3: Relative Abundance, high resolution | T37: 23
A38: 2024 | B38: Lower Fraser | C38: Paleface Creek | D38: T2 | E38: Chilliwack - Early Summer | F38: Aug. 28 - Sep. 3, 2024 | G38: Late August | H38: 7 | I38: 0 | J38: 2 | K38: 5 | L38: 77.27 | M38: 4 | N38: Five ground surveys conducted. Chilliwack-ES composite sex ratio and spawnsuccess applied. | O38: (Peak Live + Cumulative Dead)*Expansion | P38: 45512 | Q38: 45540 | R38: 5 | S38: Type-3: Relative Abundance, high resolution | T38: 23
A39: 2024 | B39: Lower Fraser | C39: Nahatlatch Lake | D39: T2 | E39: Nahatlatch - Early Summer | H39: 335 | I39: 7 | J39: 167 | K39: 161 | L39: 96.67 | M39: 156 | N39: Four ground surveys conducted. Population estimates based on IPSFC recovery/effort expansion. | O39: Lake Expansion | P39: 45530 | Q39: 45551 | R39: 4 | S39: Type-4: Relative Abundance, medium resolution | T39: 24
A40: 2024 | B40: Lower Fraser | C40: Nahatlatch River | D40: T2 | E40: Nahatlatch - Early Summer | F40: Sep. 1-8, 2024 | H40: 1528 | I40: 0 | J40: 712 | K40: 816 | L40: 91.54 | M40: 747 | N40: Four ground surveys conducted. | O40: (Peak Live + Cumulative Dead)*Expansion | P40: 45530 | Q40: 45551 | R40: 4 | S40: Type-4: Relative Abundance, medium resolution | T40: 24
...
